Workbook

Sheet الاعمال المنجزة المعدل
B1: مشروع صيانة طريق اوباري غات
B2: الاعمال المنجزة للمرحلة الاولي | AF2: التاريخ | AH2: =TODAY() -> 46197 | AL2: =AH2 -> 46197
B3: القطاع (A)
B4: البند | C4: الوصف | H4: اعمال اليوم (م.ط) | L4: الإجمالي (م.ط) | P4: المستهدف اليومي | T4: الزيادة / النقصان | W4: ملاحظات | AX4: الاعمال السابقة (م.ط)
C5: بنود أساسية | AL5: إعادة التدوير | AM5: الأساس الحبيبي | AN5: طبقة التشريب | AO5: الاسفلت المحسن | AP5: الطريق الخدمي | AQ5: المستهدف
B6: 1 | C6: طبقة إعادة التدوير (FDR) | H6: 600 | L6: =AX6+H6 -> 112243 | P6: 500 | T6: =H6-P6 -> 100 | AL6: =L6 -> 112243 | AM6: =L11 -> 109373 | AN6: =L7 -> 109373 | AO6: =L8 -> 107363 | AP6: =L12 -> 115363 | AQ6: 115363 | AX6: 111643
B7: 2 | C7: رش طبقة التشريب (MCO) | H7: 0 | L7: =AX7+H7 -> 109373 | P7: 500 | T7: =H7-P7 -> -500 | AX7: 109373
B8: 3 | C8: طبقة الاسفلت المحسن | H8: 590 | L8: =AX8+H8 -> 107363 | P8: 500 | T8: =H8-P8 -> 90 | AX8: 106773
C9: بنود إضافية
B10: 1 | C10: فرمة اولي بدون اسمنت(FDR) | H10: 0 | L10: =AX10+H10 -> 115363 | P10: 500 | T10: =H10-P10 -> -500 | AX10: 115363
B11: 2 | C11: طبقة أساس حبيبي | H11: 0 | L11: =AX11+H11 -> 109373 | P11: 500 | T11: =H11-P11 -> -500 | AX11: 109373
B12: 3 | C12: الطريق الخدمي | H12: 0 | L12: =AX12+H12 -> 115363 | AX12: 115363
B14: القطاع (B)
B15: البند | C15: الوصف | H15: اعمال اليوم (م.ط) | L15: الإجمالي (م.ط) | P15: المستهدف اليومي | T15: الزيادة / النقصان | W15: ملاحظات | AX15: الاعمال السابقة (م.ط)
C16: بنود أساسية | AL16: إعادة التدوير | AM16: الأساس الحبيبي | AN16: طبقة التشريب | AO16: الاسفلت المحسن | AP16: الطريق الخدمي | AQ16: المستهدف
B17: 1 | C17: طبقة إعادة التدوير (FDR) | H17: 460 | L17: =AX17+H17 -> 107960 | P17: 500 | T17: =H17-P17 -> -40 | AL17: =L17 -> 107960 | AM17: =L22 -> 106110 | AN17: =L18 -> 104930 | AO17: =L19 -> 102560 | AP17: =L23 -> 110900 | AQ17: 110900 | AX17: 107500
B18: 2 | C18: رش طبقة التشريب (MCO) | H18: 0 | L18: =AX18+H18 -> 104930 | P18: 500 | T18: =H18-P18 -> -500 | AX18: 104930
B19: 3 | C19: طبقة الاسفلت المحسن | H19: 0 | L19: =AX19+H19 -> 102560 | P19: 500 | T19: =H19-P19 -> -500 | AX19: 102560
C20: بنود إضافية
B21: 1 | C21: فرمة اولي بدون اسمنت(FDR) | H21: 0 | L21: =AX21+H21 -> 110780 | P21: 500 | T21: =H21-P21 -> -500 | AX21: 110780 | BB21: 140
B22: 2 | C22: طبقة أساس حبيبي | H22: 600 | L22: =AX22+H22 -> 106110 | P22: 500 | T22: =H22-P22 -> 100 | AX22: 105510
B23: 3 | C23: الطريق الخدمي | H23: 0 | L23: =AX23+H23 -> 110900 | AX23: 110900
B25: اجمالي المنجز للمرحلة الاولي
B26: البند | C26: الوصف | H26: اعمال اليوم (م.ط) | L26: الإجمالي (م.ط) | P26: الجاهز للعمل في البنذ | U26: ملاحظات | AX26: الاعمال السابقة (م.ط)
C27: بنود أساسية | AL27: إعادة التدوير | AM27: الأساس الحبيبي | AN27: طبقة التشريب | AO27: الاسفلت المحسن | AP27: الطريق الخدمي | AQ27: المستهدف
B28: 1 | C28: طبقة إعادة التدوير (FDR) | H28: =H6+H17 -> 1060 | L28: =AX28+H28 -> 220203 | P28: =L32-L28 -> 5940 | U28: الجاهز للعمل بالبنذ (منفذ فرمة اولي وغير منفذ فرمة تانية) | AL28: =L28 -> 220203 | AM28: =L33 -> 215483 | AN28: =L29 -> 214303 | AO28: =L30 -> 209923 | AP28: =L34 -> 226263 | AQ28: 226263 | AX28: =AX6+AX17 -> 219143
B29: 2 | C29: رش طبقة التشريب (MCO) | H29: =H7+H18 -> 0 | L29: =AX29+H29 -> 214303 | P29: =L33-L29 -> 1180 | U29: الجاهز للعمل بالبنذ (منفذ اساس وغير مرشوش mc) | AX29: =AX7+AX18 -> 214303
B30: 3 | C30: طبقة الاسفلت المحسن | H30: =H8+H19 -> 590 | L30: =AX30+H30 -> 209923 | P30: =L29-L30 -> 4380 | U30: الجاهز للعمل بالبنذ (مرشوش mc وغير منفذ اسفلت) | AX30: =AX8+AX19 -> 209333
C31: بنود إضافية
B32: 1 | C32: فرمة اولي بدون اسمنت(FDR) | H32: =H10+H21 -> 0 | L32: =AX32+H32 -> 226143 | P32: =226263-L32 -> 120 | U32: الجاهز للعمل بالبنذ (المتبقي من القطاع وغير مفروم فرمة اولي) | AX32: =AX10+AX21 -> 226143
B33: 2 | C33: طبقة أساس حبيبي | H33: =H11+H22 -> 600 | L33: =AX33+H33 -> 215483 | P33: =L28-L33 -> 4720 | U33: الجاهز للعمل بالبنذ (منفذ فرمة ثانية وغير منفذ اساس) | AX33: =AX11+AX22 -> 214883
B34: 3 | C34: الطريق الخدمي | H34: =H12+H23 -> 0 | L34: =AX34+H34 -> 226263 | P34: =226263-L34 -> 0 | U34: مستكمل | AX34: =AX12+AX23 -> 226263
B36: المتبقي من البنذ | H36: القطاع (A) | L36: القطاع (B) | P36: الإجمالي | AB36: المتبقي من البنذ | AH36: القطاع (A) | AL36: القطاع (B) | AP36: الإجمالي
B37: المتبقي من الفرمة الاولي | H37: =القطاعات!BL70 -> 0 | L37: =القطاعات!BR70 -> 0 | P37: =H37+L37 -> 0 | AB37: المتبقي من طبقة التشريب | AH37: =القطاعات!BL73 -> 5990 | AL37: =القطاعات!BR73 -> 5930 | AP37: =AH37+AL37 -> 11920
B38: المتبقي من الفرمة التانية | H38: =القطاعات!BL71 -> 3120 | L38: =القطاعات!BR71 -> 2900 | P38: =H38+L38 -> 6020 | AB38: المتبقي من الاسفلت | AH38: =القطاعات!BL74 -> 8000 | AL38: =القطاعات!BR74 -> 8340 | AP38: =AH38+AL38 -> 16340
B39: المتبقي من الأساس | H39: =القطاعات!BL72 -> 5990 | L39: =القطاعات!BR72 -> 4750 | P39: =H39+L39 -> 10740 | AB39: طول الطريق الخدمي العامل | AH39: =L34-L30 -> 16340 | AL39: كيلومتر

Sheet القطاعات
B3: القطاع الأول شركة حسن علام | H3: 00+000 | I3: 00+100 | J3: 00+200 | K3: 00+300 | L3: 00+400 | M3: 00+500 | N3: 00+600 | O3: 00+700 | P3: 00+800 | Q3: 00+900 | R3: 01+000 | S3: 01+100 | T3: 01+200 | U3: 01+300 | V3: 01+400 | W3: 01+500 | X3: 01+600 | Y3: 01+700 | Z3: 01+800 | AA3: 01+900 | AB3: 02+000 | AC3: 02+100 | AD3: 02+200 | AE3: 02+300 | AF3: 02+400 | AG3: 02+500 | AH3: 02+600 | AI3: 02+700 | AJ3: 02+800 | AK3: 02+900 | AL3: 03+000 | AM3: 03+100 | AN3: 03+200 | AO3: 03+300 | AP3: 03+400 | AQ3: 03+500 | AR3: 03+600 | AS3: 03+700 | AT3: 03+800 | AU3: 03+900 | AV3: 04+000 | AW3: 04+100 | AX3: 04+200 | AY3: 04+300 | AZ3: 04+400 | BA3: 04+500 | BB3: 04+600 | BC3: 04+700 | BD3: 04+800 | BE3: 04+900 | BF3: 05+000 | BG3: 05+100 | BH3: 05+200 | BI3: 05+300 | BJ3: 05+400 | BK3: 05+500 | BL3: 05+600 | BM3: 05+700 | BN3: 05+800 | BO3: 05+900 | BP3: 06+000 | BQ3: 06+100 | BR3: 06+200 | BS3: 06+300 | BT3: 06+400 | BU3: 06+500 | BV3: 06+600 | BW3: 06+700 | BX3: 06+800 | BY3: 06+900 | BZ3: 07+000 | CA3: 07+100 | CB3: 07+200 | CC3: 07+300 | CD3: 07+400 | CE3: 07+500 | CF3: 07+600 | CG3: 07+700 | CH3: 07+800 | CI3: 07+900 | CJ3: 08+000 | CK3: 08+100 | CL3: 08+200 | CM3: 08+300 | CN3: 08+400 | CO3: 08+500 | CP3: 08+600 | CQ3: 08+700 | CR3: 08+800 | CS3: 08+900 | CT3: 09+000 | CU3: 09+100 | CV3: 09+200 | CW3: 09+300 | CX3: 09+400 | CY3: 09+500 | CZ3: 09+600 | DA3: 09+700 | DB3: 09+800 | DC3: 09+900 | DD3: 10+000 | DE3: 10+100 | DF3: 10+200 | DG3: 10+300 | DH3: 10+400 | DI3: 10+500 | DJ3: 10+600 | DK3: 10+700 | DL3: 10+800 | DM3: 10+900 | DN3: 11+000 | DO3: 11+100 | DP3: 11+200 | DQ3: 11+300 | DR3: 11+400 | DS3: 11+500 | DT3: 11+600 | DU3: 11+700 | DV3: 11+800 | DW3: 11+900 | DX3: 12+000 | DY3: 12+100 | DZ3: 12+200 | EA3: 12+300 | EB3: 12+400 | EC3: 12+500 | ED3: 12+600 | EE3: 12+700 | EF3: 12+800 | EG3: 12+900 | EH3: 13+000 | EI3: 13+100 | EJ3: 13+200 | EK3: 13+300 | EL3: 13+400 | EM3: 13+500 | EN3: 13+600 | EO3: 13+700 | EP3: 13+800 | EQ3: 13+900 | ER3: 14+000 | ES3: 14+100 | ET3: 14+200 | EU3: 14+300 | EV3: 14+400 | EW3: 14+500 | EX3: 14+600 | EY3: 14+700 | EZ3: 14+800 | FA3: 14+900 | FB3: 15+000 | FC3: 15+100 | FD3: 15+200 | FE3: 15+300 | FF3: 15+400 | FG3: 15+500 | FH3: 15+600 | FI3: 15+700 | FJ3: 15+800 | FK3: 15+900 | FL3: 16+000 | FM3: 16+100 | FN3: 16+200 | FO3: 16+300 | FP3: 16+400 | FQ3: 16+500 | FR3: 16+600 | FS3: 16+700 | FT3: 16+800 | FU3: 16+900 | FV3: 17+000 | FW3: 17+100 | FX3: 17+200 | FY3: 17+300 | FZ3: 17+400 | GA3: 17+500 | GB3: 17+600 | GC3: 17+700 | GD3: 17+800 | GE3: 17+900 | GF3: 18+000 | GG3: 18+100 | GH3: 18+200 | GI3: 18+300 | GJ3: 18+400 | GK3: 18+500 | GL3: 18+600 | GM3: 18+700 | GN3: 18+800 | GO3: 18+900 | GP3: 19+000 | GQ3: 19+100 | GR3: 19+200 | GS3: 19+300 | GT3: 19+400 | GU3: 19+500 | GV3: 19+600 | GW3: 19+700 | GX3: 19+800 | GY3: 19+900 | GZ3: 20+000 | HA3: 20+100 | HB3: 20+200 | HC3: 20+300 | HD3: 20+400 | HE3: 20+500 | HF3: 20+600 | HG3: 20+700 | HH3: 20+800 | HI3: 20+900 | HJ3: 21+000 | HK3: 21+100 | HL3: 21+200 | HM3: 21+300 | HN3: 21+400 | HO3: 21+500 | HP3: 21+600 | HQ3: 21+700 | HR3: 21+800 | HS3: 21+900 | HT3: 22+000 | HU3: 22+100 | HV3: 22+200 | HW3: 22+300 | HX3: 22+400 | HY3: 22+500 | HZ3: 22+600 | IA3: 22+700 | IB3: 22+800 | IC3: 22+900 | ID3: 23+000 | IE3: 23+100 | IF3: 23+200 | IG3: 23+300 | IH3: 23+400 | II3: 23+500 | IJ3: 23+600 | IK3: 23+700 | IL3: 23+800 | IM3: 23+900 | IN3: 24+000 | IO3: 24+100 | IP3: 24+200 | IQ3: 24+300 | IR3: 24+400 | IS3: 24+500 | IT3: 24+600 | IU3: 24+700 | IV3: 24+800 | IW3: 24+900 | IX3: 25+000 | IY3: 25+100 | IZ3: 25+200 | JA3: 25+300 | JB3: 25+400 | JC3: 25+500 | JD3: 25+600 | JE3: 25+700 | JF3: 25+800 | JG3: 25+900 | JH3: 26+000 | JI3: 26+100 | JJ3: 26+200 | JK3: 26+300 | JL3: 26+400 | JM3: 26+500 | JN3: 26+600 | JO3: 26+700 | JP3: 26+800 | JQ3: 26+900 | JR3: 27+000 | JS3: 27+100 | JT3: 27+200 | JU3: 27+300 | JV3: 27+400 | JW3: 27+500 | JX3: 27+600 | JY3: 27+700 | JZ3: 27+800 | KA3: 27+900 | KB3: 28+000 | KC3: 28+100 | KD3: 28+200 | KE3: 28+300 | KF3: 28+400 | KG3: 28+500 | KH3: 28+600 | KI3: 28+700 | KJ3: 28+800 | KK3: 28+900 | KL3: 29+000 | KM3: 29+100 | KN3: 29+200 | KO3: 29+300 | KP3: 29+400 | KQ3: 29+500 | KR3: 29+600 | KS3: 29+700 | KT3: 29+800 | KU3: 29+900 | KV3: 30+000 | KW3: 30+100 | KX3: 30+200 | KY3: 30+300 | KZ3: 30+400 | LA3: 30+500 | LB3: 30+600 | LC3: 30+700 | LD3: 30+800 | LE3: 30+900 | LF3: 31+000 | LG3: 31+100 | LH3: 31+200 | LI3: 31+300 | LJ3: 31+400 | LK3: 31+500 | LL3: 31+600 | LM3: 31+700 | LN3: 31+800 | LO3: 31+900 | LP3: 32+000 | LQ3: 32+100 | LR3: 32+200 | LS3: 32+300 | LT3: 32+400 | LU3: 32+500 | LV3: 32+600 | LW3: 32+700 | LX3: 32+800 | LY3: 32+900 | LZ3: 33+000 | MA3: 33+100 | MB3: 33+200 | MC3: 33+300 | MD3: 33+400 | ME3: 33+500 | MF3: 33+600 | MG3: 33+700 | MH3: 33+800 | MI3: 33+900 | MJ3: 34+000 | MK3: 34+100 | ML3: 34+200 | MM3: 34+300 | MN3: 34+400 | MO3: 34+500 | MP3: 34+600 | MQ3: 34+700 | MR3: 34+800 | MS3: 34+900 | MT3: 35+000 | MU3: 35+100 | MV3: 35+200 | MW3: 35+300 | MX3: 35+400 | MY3: 35+500 | MZ3: 35+600 | NA3: 35+700 | NB3: 35+800 | NC3: 35+900 | ND3: 36+000 | NE3: 36+100 | NF3: 36+200 | NG3: 36+300 | NH3: 36+400 | NI3: 36+500 | NJ3: 36+600 | NK3: 36+700 | NL3: 36+800 | NM3: 36+900 | NN3: 37+000 | NO3: 37+100 | NP3: 37+200 | NQ3: 37+300 | NR3: 37+400 | NS3: 37+500 | NT3: 37+600 | NU3: 37+700 | NV3: 37+800 | NW3: 37+900 | NX3: 38+000 | NY3: 38+100 | NZ3: 38+200 | OA3: 38+300 | OB3: 38+400 | OC3: 38+500 | OD3: 38+600 | OE3: 38+700 | OF3: 38+800 | OG3: 38+900 | OH3: 39+000 | OI3: 39+100 | OJ3: 39+200 | OK3: 39+300 | OL3: 39+400 | OM3: 39+500 | ON3: 39+600 | OO3: 39+700 | OP3: 39+800 | OQ3: 39+900 | OR3: 40+000 | OS3: 40+100 | OT3: 40+200 | OU3: 40+300 | OV3: 40+400 | OW3: 40+500 | OX3: 40+600 | OY3: 40+700 | OZ3: 40+800 | PA3: 40+900 | PB3: 41+000 | PC3: 41+100 | PD3: 41+200 | PE3: 41+300 | PF3: 41+400 | PG3: 41+500 | PH3: 41+600 | PI3: 41+700 | PJ3: 41+800 | PK3: 41+900 | PL3: 42+000 | PM3: 42+100 | PN3: 42+200 | PO3: 42+300 | PP3: 42+400 | PQ3: 42+500 | PR3: 42+600 | PS3: 42+700 | PT3: 42+800 | PU3: 42+900 | PV3: 43+000 | PW3: 43+100 | PX3: 43+200 | PY3: 43+300 | PZ3: 43+400 | QA3: 43+500 | QB3: 43+600 | QC3: 43+700 | QD3: 43+800 | QE3: 43+900 | QF3: 44+000 | QG3: 44+100 | QH3: 44+200 | QI3: 44+300 | QJ3: 44+400 | QK3: 44+500 | QL3: 44+600 | QM3: 44+700 | QN3: 44+800 | QO3: 44+900 | QP3: 45+000
C4: بنود أساسية
B5: 1 | C5: طبقة إعادة التدوير (FDR) | AP5: 03+430 | BK5: 05+540 | KO5: 29+335 | KV5: 30+000 | LI5: 31+370 | LO5: 31+980 | MC5: 33+370 | MH5: 33+840
B6: 2 | C6: رش طبقة التشريب (MCO) | BK6: 05+550 | DG6: 10+320 | DN6: 11+010 | JA6: 25+400 | JF6: 25+840 | JI6: 26+140 | JW6: 27+500 | KA6: 27+900 | KD6: 28+200 | KG6: 28+500 | KM6: 29+100 | KS6: 29+770 | KU6: 29+990 | LR6: 32+240 | LZ6: 33+080
B7: 3 | C7: طبقة الاسفلت المحسن | BM7: 05+710 | DG7: 10+300 | DN7: 11+020 | EV7: 14+430 | FB7: 15+000 | FJ7: 15+800 | FX7: 17+205 | GE7: 17+940 | GI7: 18+310 | HR7: 21+855 | HY7: 22+550 | II7: 23+550 | IR7: 24+400 | JH7: 26+120 | KC7: 28+150 | KN7: 29+200. | KU7: 29+950 | MK7: 34+120 | MY7: 35+580
C8: بنود إضافية
B9: 1 | C9: طبقة أساس حبيبي | BK9: 05+550 | DG9: 10+320 | DN9: 11+010 | JA9: 25+400 | JF9: 25+850 | JI9: 26+150 | JP9: 26+850 | JW9: 27+500 | KA9: 27+900 | KD9: 28+200 | KG9: 28+500 | KM9: 29+100 | KR9: 29+600 | KS9: 29+770 | KV9: 30+000 | LR9: 32+250 | LV9: 32+620 | LX9: 32+800 | ME9: 33+500
B10: 2 | C10: الطريق الخدمي | AP10: 03+430 | BK10: 05+550 | HF10: 65+580
B12: القطاع التاني شركة نيوم | H12: 45+000 | I12: 45+100 | J12: 45+200 | K12: 45+300 | L12: 45+400 | M12: 45+500 | N12: 45+600 | O12: 45+700 | P12: 45+800 | Q12: 45+900 | R12: 46+000 | S12: 46+100 | T12: 46+200 | U12: 46+300 | V12: 46+400 | W12: 46+500 | X12: 46+600 | Y12: 46+700 | Z12: 46+800 | AA12: 46+900 | AB12: 47+000 | AC12: 47+100 | AD12: 47+200 | AE12: 47+300 | AF12: 47+400 | AG12: 47+500 | AH12: 47+600 | AI12: 47+700 | AJ12: 47+800 | AK12: 47+900 | AL12: 48+000 | AM12: 48+100 | AN12: 48+200 | AO12: 48+300 | AP12: 48+400 | AQ12: 48+500 | AR12: 48+600 | AS12: 48+700 | AT12: 48+800 | AU12: 48+900 | AV12: 49+000 | AW12: 49+100 | AX12: 49+200 | AY12: 49+300 | AZ12: 49+400 | BA12: 49+500 | BB12: 49+600 | BC12: 49+700 | BD12: 49+800 | BE12: 49+900 | BF12: 50+000 | BG12: 50+100 | BH12: 50+200 | BI12: 50+300 | BJ12: 50+400 | BK12: 50+500 | BL12: 50+600 | BM12: 50+700 | BN12: 50+800 | BO12: 50+900 | BP12: 51+000 | BQ12: 51+100 | BR12: 51+200 | BS12: 51+300 | BT12: 51+400 | BU12: 51+500 | BV12: 51+600 | BW12: 51+700 | BX12: 51+800 | BY12: 51+900 | BZ12: 52+000 | CA12: 52+100 | CB12: 52+200 | CC12: 52+300 | CD12: 52+400 | CE12: 52+500 | CF12: 52+600 | CG12: 52+700 | CH12: 52+800 | CI12: 52+900 | CJ12: 53+000 | CK12: 53+100 | CL12: 53+200 | CM12: 53+300 | CN12: 53+400 | CO12: 53+500 | CP12: 53+600 | CQ12: 53+700 | CR12: 53+800 | CS12: 53+900 | CT12: 54+000 | CU12: 54+100 | CV12: 54+200 | CW12: 54+300 | CX12: 54+400 | CY12: 54+500 | CZ12: 54+600 | DA12: 54+700 | DB12: 54+800 | DC12: 54+900 | DD12: 55+000 | DE12: 55+100 | DF12: 55+200 | DG12: 55+300 | DH12: 55+400 | DI12: 55+500 | DJ12: 55+600 | DK12: 55+700 | DL12: 55+800 | DM12: 55+900 | DN12: 56+000 | DO12: 56+100 | DP12: 56+200 | DQ12: 56+300 | DR12: 56+400 | DS12: 56+500 | DT12: 56+600 | DU12: 56+700 | DV12: 56+800 | DW12: 56+900 | DX12: 57+000 | DY12: 57+100 | DZ12: 57+200 | EA12: 57+300 | EB12: 57+400 | EC12: 57+500 | ED12: 57+600 | EE12: 57+700 | EF12: 57+800 | EG12: 57+900 | EH12: 58+000 | EI12: 58+100 | EJ12: 58+200 | EK12: 58+300 | EL12: 58+400 | EM12: 58+500 | EN12: 58+600 | EO12: 58+700 | EP12: 58+800 | EQ12: 58+900 | ER12: 59+000 | ES12: 59+100 | ET12: 59+200 | EU12: 59+300 | EV12: 59+400 | EW12: 59+500 | EX12: 59+600 | EY12: 59+700 | EZ12: 59+800 | FA12: 59+900 | FB12: 60+000 | FC12: 60+100 | FD12: 60+200 | FE12: 60+300 | FF12: 60+400 | FG12: 60+500 | FH12: 60+600 | FI12: 60+700 | FJ12: 60+800 | FK12: 60+900 | FL12: 61+000 | FM12: 61+100 | FN12: 61+200 | FO12: 61+300 | FP12: 61+400 | FQ12: 61+500 | FR12: 61+600 | FS12: 61+700 | FT12: 61+800 | FU12: 61+900 | FV12: 62+000 | FW12: 62+100 | FX12: 62+200 | FY12: 62+300 | FZ12: 62+400 | GA12: 62+500 | GB12: 62+600 | GC12: 62+700 | GD12: 62+800 | GE12: 62+900 | GF12: 63+000 | GG12: 63+100 | GH12: 63+200 | GI12: 63+300 | GJ12: 63+400 | GK12: 63+500 | GL12: 63+600 | GM12: 63+700 | GN12: 63+800 | GO12: 63+900 | GP12: 64+000 | GQ12: 64+100 | GR12: 64+200 | GS12: 64+300 | GT12: 64+400 | GU12: 64+500 | GV12: 64+600 | GW12: 64+700 | GX12: 64+800 | GY12: 64+900 | GZ12: 65+000 | HA12: 65+100 | HB12: 65+200 | HC12: 65+300 | HD12: 65+400 | HE12: 65+500 | HF12: 65+600 | HG12: 65+700 | HH12: 65+800 | HI12: 65+900 | HJ12: 66+000 | HK12: 66+100 | HL12: 66+200 | HM12: 66+300 | HN12: 66+400 | HO12: 66+500 | HP12: 66+600 | HQ12: 66+700 | HR12: 66+800 | HS12: 66+900 | HT12: 67+000 | HU12: 67+100 | HV12: 67+200 | HW12: 67+300 | HX12: 67+400 | HY12: 67+500 | HZ12: 67+600 | IA12: 67+700 | IB12: 67+800 | IC12: 67+900 | ID12: 68+000 | IE12: 68+100 | IF12: 68+200 | IG12: 68+300 | IH12: 68+400 | II12: 68+500 | IJ12: 68+600 | IK12: 68+700 | IL12: 68+800 | IM12: 68+900 | IN12: 69+000 | IO12: 69+100 | IP12: 69+200 | IQ12: 69+300 | IR12: 69+400 | IS12: 69+500 | IT12: 69+600 | IU12: 69+700 | IV12: 69+800 | IW12: 69+900 | IX12: 70+000 | IY12: 70+100 | IZ12: 70+200 | JA12: 70+300 | JB12: 70+400 | JC12: 70+500 | JD12: 70+600 | JE12: 70+700 | JF12: 70+800 | JG12: 70+900
C13: بنود أساسية
B14: 1 | C14: طبقة إعادة التدوير (FDR) | N14: 45+580 | EO14: 58+730 | ES14: 59+030 | FA14: 59+930 | FC14: 60+080 | GG14: 63+080
B15: 2 | C15: رش طبقة التشريب (MCO) | N15: 45+580 | P15: 45+880 | Q15: 45+970 | AA15: 46+870 | BJ15: 50+400 | BO15: 50+990 | BU15: 51+510 | BX15: 51+800 | CA15: 52+100 | CJ15: 53+050 | DL15: 55+850 | DR15: 56+400 | EX15: 59+630 | FA15: 59+920 | FC15: 60+090 | FT15: 61+825 | GD15: 62+280 | GF15: 63+000
B16: 3 | C16: طبقة الاسفلت المحسن | DA16: 54+717
C17: بنود إضافية
B18: 1 | C18: طبقة أساس حبيبي | N18: 45+580 | Q18: 45+970 | V18: 46+470 | Y18: 46+670 | BJ18: 50+400 | BL18: 50+600 | BP18: 51+000 | BS18: 51+300 | BV18: 51+600 | BX18: 51+800 | CE18: 52+480 | CY18: 54+500 | DT18: 56+650 | EH18: 58+050 | EX18: 59+630 | FA18: 59+920 | FC18: 60+090 | GF18: 63+000
B19: 2 | C19: الطريق الخدمي | N19: 45+580 | HF19: 65+580
B22: القطاع الثالث شركة اوراسكوم | H22: 90+000 | I22: 90+100 | J22: 90+200 | K22: 90+300 | L22: 90+400 | M22: 90+500 | N22: 90+600 | O22: 90+700 | P22: 90+800 | Q22: 90+900 | R22: 91+000 | S22: 91+100 | T22: 91+200 | U22: 91+300 | V22: 91+400 | W22: 91+500 | X22: 91+600 | Y22: 91+700 | Z22: 91+800 | AA22: 91+900 | AB22: 92+000 | AC22: 92+100 | AD22: 92+200 | AE22: 92+300 | AF22: 92+400 | AG22: 92+500 | AH22: 92+600 | AI22: 92+700 | AJ22: 92+800 | AK22: 92+900 | AL22: 93+000 | AM22: 93+100 | AN22: 93+200 | AO22: 93+300 | AP22: 93+400 | AQ22: 93+500 | AR22: 93+600 | AS22: 93+700 | AT22: 93+800 | AU22: 93+900 | AV22: 94+000 | AW22: 94+100 | AX22: 94+200 | AY22: 94+300 | AZ22: 94+400 | BA22: 94+500 | BB22: 94+600 | BC22: 94+700 | BD22: 94+800 | BE22: 94+900 | BF22: 95+000 | BG22: 95+100 | BH22: 95+200 | BI22: 95+300 | BJ22: 95+400 | BK22: 95+500 | BL22: 95+600 | BM22: 95+700 | BN22: 95+800 | BO22: 95+900 | BP22: 96+000 | BQ22: 96+100 | BR22: 96+200 | BS22: 96+300 | BT22: 96+400 | BU22: 96+500 | BV22: 96+600 | BW22: 96+700 | BX22: 96+800 | BY22: 96+900 | BZ22: 97+000 | CA22: 97+100 | CB22: 97+200 | CC22: 97+300 | CD22: 97+400 | CE22: 97+500 | CF22: 97+600 | CG22: 97+700 | CH22: 97+800 | CI22: 97+900 | CJ22: 98+000 | CK22: 98+100 | CL22: 98+200 | CM22: 98+300 | CN22: 98+400 | CO22: 98+500 | CP22: 98+600 | CQ22: 98+700 | CR22: 98+800 | CS22: 98+900 | CT22: 99+000 | CU22: 99+100 | CV22: 99+200 | CW22: 99+300 | CX22: 99+400 | CY22: 99+500 | CZ22: 99+600 | DA22: 99+700 | DB22: 99+800 | DC22: 99+900 | DD22: 100+000 | DE22: 100+100 | DF22: 100+200 | DG22: 100+300 | DH22: 100+400 | DI22: 100+500 | DJ22: 100+600 | DK22: 100+700 | DL22: 100+800 | DM22: 100+900 | DN22: 101+000 | DO22: 101+100 | DP22: 101+200 | DQ22: 101+300 | DR22: 101+400 | DS22: 101+500 | DT22: 101+600 | DU22: 101+700 | DV22: 101+800 | DW22: 101+900 | DX22: 102+000 | DY22: 102+100 | DZ22: 102+200 | EA22: 102+300 | EB22: 102+400 | EC22: 102+500 | ED22: 102+600 | EE22: 102+700 | EF22: 102+800 | EG22: 102+900 | EH22: 103+000 | EI22: 103+100 | EJ22: 103+200 | EK22: 103+300 | EL22: 103+400 | EM22: 103+500 | EN22: 103+600 | EO22: 103+700 | EP22: 103+800 | EQ22: 103+900 | ER22: 104+000 | ES22: 104+100 | ET22: 104+200 | EU22: 104+300 | EV22: 104+400 | EW22: 104+500 | EX22: 104+600 | EY22: 104+700 | EZ22: 104+800 | FA22: 104+900 | FB22: 105+000 | FC22: 105+100 | FD22: 105+200 | FE22: 105+300 | FF22: 105+400 | FG22: 105+500 | FH22: 105+600 | FI22: 105+700 | FJ22: 105+800 | FK22: 105+900 | FL22: 106+000 | FM22: 106+100 | FN22: 106+200 | FO22: 106+300 | FP22: 106+400 | FQ22: 106+500 | FR22: 106+600 | FS22: 106+700 | FT22: 106+800 | FU22: 106+900 | FV22: 107+000 | FW22: 107+100 | FX22: 107+200 | FY22: 107+300 | FZ22: 107+400 | GA22: 107+500 | GB22: 107+600 | GC22: 107+700 | GD22: 107+800 | GE22: 107+900 | GF22: 108+000 | GG22: 108+100 | GH22: 108+200 | GI22: 108+300 | GJ22: 108+400 | GK22: 108+500 | GL22: 108+600 | GM22: 108+700 | GN22: 108+800 | GO22: 108+900 | GP22: 109+000 | GQ22: 109+100 | GR22: 109+200 | GS22: 109+300 | GT22: 109+400 | GU22: 109+500 | GV22: 109+600 | GW22: 109+700 | GX22: 109+800 | GY22: 109+900 | GZ22: 110+000 | HA22: 110+100 | HB22: 110+200 | HC22: 110+300 | HD22: 110+400 | HE22: 110+500 | HF22: 110+600 | HG22: 110+700 | HH22: 110+800 | HI22: 110+900 | HJ22: 111+000 | HK22: 111+100 | HL22: 111+200 | HM22: 111+300 | HN22: 111+400 | HO22: 111+500 | HP22: 111+600 | HQ22: 111+700 | HR22: 111+800 | HS22: 111+900 | HT22: 112+000 | HU22: 112+100 | HV22: 112+200 | HW22: 112+300 | HX22: 112+400 | HY22: 112+500 | HZ22: 112+600 | IA22: 112+700 | IB22: 112+800 | IC22: 112+900 | ID22: 113+000 | IE22: 113+100 | IF22: 113+200 | IG22: 113+300 | IH22: 113+400 | II22: 113+500 | IJ22: 113+600 | IK22: 113+700 | IL22: 113+800 | IM22: 113+900 | IN22: 114+000 | IO22: 114+100 | IP22: 114+200 | IQ22: 114+300 | IR22: 114+400 | IS22: 114+500 | IT22: 114+600 | IU22: 114+700 | IV22: 114+800 | IW22: 114+900 | IX22: 115+000 | IY22: 115+100 | IZ22: 115+200 | JA22: 115+300 | JB22: 115+400 | JC22: 115+500 | JD22: 115+600 | JE22: 115+700 | JF22: 115+800 | JG22: 115+900 | JH22: 116+000 | JI22: 116+100 | JJ22: 116+200 | JK22: 116+300 | JL22: 116+400 | JM22: 116+500 | JN22: 116+600 | JO22: 116+700 | JP22: 116+800 | JQ22: 116+900 | JR22: 117+000 | JS22: 117+100 | JT22: 117+200 | JU22: 117+300 | JV22: 117+400 | JW22: 117+500 | JX22: 117+600 | JY22: 117+700 | JZ22: 117+800 | KA22: 117+900 | KB22: 118+000 | KC22: 118+100 | KD22: 118+200 | KE22: 118+300 | KF22: 118+400 | KG22: 118+500 | KH22: 118+600 | KI22: 118+700 | KJ22: 118+800 | KK22: 118+900 | KL22: 119+000 | KM22: 119+100 | KN22: 119+200 | KO22: 119+300 | KP22: 119+400 | KQ22: 119+500 | KR22: 119+600 | KS22: 119+700 | KT22: 119+800 | KU22: 119+900 | KV22: 120+000 | KW22: 120+100 | KX22: 120+200 | KY22: 120+300 | KZ22: 120+400 | LA22: 120+500 | LB22: 120+600 | LC22: 120+700 | LD22: 120+800 | LE22: 120+900 | LF22: 121+000 | LG22: 121+100 | LH22: 121+200 | LI22: 121+300 | LJ22: 121+400 | LK22: 121+500 | LL22: 121+600 | LM22: 121+700 | LN22: 121+800 | LO22: 121+900 | LP22: 122+000 | LQ22: 122+100 | LR22: 122+200 | LS22: 122+300 | LT22: 122+400 | LU22: 122+500 | LV22: 122+600 | LW22: 122+700 | LX22: 122+800 | LY22: 122+900 | LZ22: 123+000 | MA22: 123+100 | MB22: 123+200 | MC22: 123+300 | MD22: 123+400 | ME22: 123+500 | MF22: 123+600 | MG22: 123+700 | MH22: 123+800 | MI22: 123+900 | MJ22: 124+000 | MK22: 124+100 | ML22: 124+200 | MM22: 124+300 | MN22: 124+400 | MO22: 124+500 | MP22: 124+600 | MQ22: 124+700 | MR22: 124+800 | MS22: 124+900 | MT22: 125+000 | MU22: 125+100 | MV22: 125+200 | MW22: 125+300 | MX22: 125+400 | MY22: 125+500 | MZ22: 125+600 | NA22: 125+700 | NB22: 125+800 | NC22: 125+900 | ND22: 126+000 | NE22: 126+100 | NF22: 126+200 | NG22: 126+300 | NH22: 126+400 | NI22: 126+500 | NJ22: 126+600 | NK22: 126+700 | NL22: 126+800 | NM22: 126+900 | NN22: 127+000 | NO22: 127+100 | NP22: 127+200 | NQ22: 127+300 | NR22: 127+400 | NS22: 127+500 | NT22: 127+600 | NU22: 127+700 | NV22: 127+800 | NW22: 127+900 | NX22: 128+000 | NY22: 128+100 | NZ22: 128+200 | OA22: 128+300 | OB22: 128+400 | OC22: 128+500 | OD22: 128+600 | OE22: 128+700 | OF22: 128+800 | OG22: 128+900 | OH22: 129+000 | OI22: 129+100 | OJ22: 129+200 | OK22: 129+300 | OL22: 129+400 | OM22: 129+500 | ON22: 129+600 | OO22: 129+700 | OP22: 129+800 | OQ22: 129+900 | OR22: 130+000 | OS22: 130+100 | OT22: 130+200 | OU22: 130+300 | OV22: 130+400 | OW22: 130+500 | OX22: 130+600 | OY22: 130+700 | OZ22: 130+800 | PA22: 130+900 | PB22: 131+000 | PC22: 131+100 | PD22: 131+200 | PE22: 131+300 | PF22: 131+400 | PG22: 131+500 | PH22: 131+600 | PI22: 131+700 | PJ22: 131+800 | PK22: 131+900 | PL22: 132+000 | PM22: 132+100 | PN22: 132+200 | PO22: 132+300 | PP22: 132+400 | PQ22: 132+500 | PR22: 132+600 | PS22: 132+700 | PT22: 132+800 | PU22: 132+900 | PV22: 133+000 | PW22: 133+100 | PX22: 133+200 | PY22: 133+300 | PZ22: 133+400 | QA22: 133+500 | QB22: 133+600 | QC22: 133+700 | QD22: 133+800 | QE22: 133+900 | QF22: 134+000 | QG22: 134+100 | QH22: 134+200 | QI22: 134+300 | QJ22: 134+400 | QK22: 134+500 | QL22: 134+600 | QM22: 134+700 | QN22: 134+800 | QO22: 134+900 | QP22: 135+000 | QQ22: 135+100 | QR22: 135+200 | QS22: 135+300 | QT22: 135+400 | QU22: 135+500
C23: بنود أساسية
B24: 1 | C24: طبقة إعادة التدوير (FDR) | M24: 90+580 | FR24: 106+630 | GN24: 108+880
B25: 2 | C25: رش طبقة التشريب (MCO) | M25: 90+580 | CX25: 99+500 | DG25: 100+300 | DK25: 100+700 | DQ25: 101+300 | DY25: 102+100 | EA25: 102+300 | EI25: 103+100 | EW25: 104+500 | FA25: 104+890 | FK25: 105+900 | FR25: 106+600
B26: 3 | C26: طبقة الاسفلت المحسن | M26: 90+580 | V26: 91+470 | AB26: 92+060 | AI26: 92+720 | AQ26: 93+535 | EK26: 103+320 | FR26: 106+550
C27: بنود إضافية
B28: 1 | C28: طبقة أساس حبيبي | M28: 90+580 | CX28: 99+500 | DG28: 100+300 | DK28: 100+700 | DQ28: 101+300 | DS28: 101+500 | DU28: 101+700 | DY28: 102+100 | EC28: 102+500 | EI28: 103+100 | EM28: 103+500 | EQ28: 103+900 | EW28: 104+500 | FA28: 104+900 | FD28: 105+100 | FG28: 105+500 | FK28: 105+900 | FR28: 106+600
B29: 2 | C29: الطريق الخدمي | H29: 90+000 | GE29: 108+000
B32: القطاع الرابع شركة الرواد | H32: 180+000 | I32: 180+100 | J32: 180+200 | K32: 180+300 | L32: 180+400 | M32: 180+500 | N32: 180+600 | O32: 180+700 | P32: 180+800 | Q32: 180+900 | R32: 181+000 | S32: 181+100 | T32: 181+200 | U32: 181+300 | V32: 181+400 | W32: 181+500 | X32: 181+600 | Y32: 181+700 | Z32: 181+800 | AA32: 181+900 | AB32: 182+000 | AC32: 182+100 | AD32: 182+200 | AE32: 182+300 | AF32: 182+400 | AG32: 182+500 | AH32: 182+600 | AI32: 182+700 | AJ32: 182+800 | AK32: 182+900 | AL32: 183+000 | AM32: 183+100 | AN32: 183+200 | AO32: 183+300 | AP32: 183+400 | AQ32: 183+500 | AR32: 183+600 | AS32: 183+700 | AT32: 183+800 | AU32: 183+900 | AV32: 184+000 | AW32: 184+100 | AX32: 184+200 | AY32: 184+300 | AZ32: 184+400 | BA32: 184+500 | BB32: 184+600 | BC32: 184+700 | BD32: 184+800 | BE32: 184+900 | BF32: 185+000 | BG32: 185+100 | BH32: 185+200 | BI32: 185+300 | BJ32: 185+400 | BK32: 185+500 | BL32: 185+600 | BM32: 185+700 | BN32: 185+800 | BO32: 185+900 | BP32: 186+000 | BQ32: 186+100 | BR32: 186+200 | BS32: 186+300 | BT32: 186+400 | BU32: 186+500 | BV32: 186+600 | BW32: 186+700 | BX32: 186+800 | BY32: 186+900 | BZ32: 187+000 | CA32: 187+100 | CB32: 187+200 | CC32: 187+300 | CD32: 187+400 | CE32: 187+500 | CF32: 187+600 | CG32: 187+700 | CH32: 187+800 | CI32: 187+900 | CJ32: 188+000 | CK32: 188+100 | CL32: 188+200 | CM32: 188+300 | CN32: 188+400 | CO32: 188+500 | CP32: 188+600 | CQ32: 188+700 | CR32: 188+800 | CS32: 188+900 | CT32: 189+000 | CU32: 189+100 | CV32: 189+200 | CW32: 189+300 | CX32: 189+400 | CY32: 189+500 | CZ32: 189+600 | DA32: 189+700 | DB32: 189+800 | DC32: 189+900 | DD32: 190+000 | DE32: 190+100 | DF32: 190+200 | DG32: 190+300 | DH32: 190+400 | DI32: 190+500 | DJ32: 190+600 | DK32: 190+700 | DL32: 190+800 | DM32: 190+900 | DN32: 191+000 | DO32: 191+100 | DP32: 191+200 | DQ32: 191+300 | DR32: 191+400 | DS32: 191+500 | DT32: 191+600 | DU32: 191+700 | DV32: 191+800 | DW32: 191+900 | DX32: 192+000 | DY32: 192+100 | DZ32: 192+200 | EA32: 192+300 | EB32: 192+400 | EC32: 192+500 | ED32: 192+600 | EE32: 192+700 | EF32: 192+800 | EG32: 192+900 | EH32: 193+000 | EI32: 193+100 | EJ32: 193+200 | EK32: 193+300 | EL32: 193+400 | EM32: 193+500 | EN32: 193+600 | EO32: 193+700 | EP32: 193+800 | EQ32: 193+900 | ER32: 194+000 | ES32: 194+100 | ET32: 194+200 | EU32: 194+300 | EV32: 194+400 | EW32: 194+500 | EX32: 194+600 | EY32: 194+700 | EZ32: 194+800 | FA32: 194+900 | FB32: 195+000 | FC32: 195+100 | FD32: 195+200 | FE32: 195+300 | FF32: 195+400 | FG32: 195+500 | FH32: 195+600 | FI32: 195+700 | FJ32: 195+800 | FK32: 195+900 | FL32: 196+000 | FM32: 196+100 | FN32: 196+200 | FO32: 196+300 | FP32: 196+400 | FQ32: 196+500 | FR32: 196+600 | FS32: 196+700 | FT32: 196+800 | FU32: 196+900 | FV32: 197+000 | FW32: 197+100 | FX32: 197+200 | FY32: 197+300 | FZ32: 197+400 | GA32: 197+500 | GB32: 197+600 | GC32: 197+700 | GD32: 197+800 | GE32: 197+900 | GF32: 198+000 | GG32: 198+100 | GH32: 198+200 | GI32: 198+300 | GJ32: 198+400 | GK32: 198+500 | GL32: 198+600 | GM32: 198+700 | GN32: 198+800 | GO32: 198+900 | GP32: 199+000 | GQ32: 199+100 | GR32: 199+200 | GS32: 199+300 | GT32: 199+400 | GU32: 199+500 | GV32: 199+600 | GW32: 199+700 | GX32: 199+800 | GY32: 199+900 | GZ32: 200+000 | HA32: 200+100 | HB32: 200+200 | HC32: 200+300 | HD32: 200+400 | HE32: 200+500 | HF32: 200+600 | HG32: 200+700 | HH32: 200+800 | HI32: 200+900 | HJ32: 201+000 | HK32: 201+100 | HL32: 201+200 | HM32: 201+300 | HN32: 201+400 | HO32: 201+500 | HP32: 201+600 | HQ32: 201+700 | HR32: 201+800 | HS32: 201+900 | HT32: 202+000 | HU32: 202+100 | HV32: 202+200 | HW32: 202+300 | HX32: 202+400 | HY32: 202+500 | HZ32: 202+600 | IA32: 202+700 | IB32: 202+800 | IC32: 202+900 | ID32: 203+000 | IE32: 203+100 | IF32: 203+200 | IG32: 203+300 | IH32: 203+400 | II32: 203+500 | IJ32: 203+600 | IK32: 203+700 | IL32: 203+800 | IM32: 203+900 | IN32: 204+000 | IO32: 204+100 | IP32: 204+200 | IQ32: 204+300 | IR32: 204+400 | IS32: 204+500 | IT32: 204+600 | IU32: 204+700 | IV32: 204+800 | IW32: 204+900 | IX32: 205+000 | IY32: 205+100 | IZ32: 205+200 | JA32: 205+300 | JB32: 205+400 | JC32: 205+500 | JD32: 205+600 | JE32: 205+700 | JF32: 205+800 | JG32: 205+900 | JH32: 206+000 | JI32: 206+100 | JJ32: 206+200 | JK32: 206+300 | JL32: 206+400 | JM32: 206+500 | JN32: 206+600 | JO32: 206+700 | JP32: 206+800 | JQ32: 206+900 | JR32: 207+000 | JS32: 207+100 | JT32: 207+200 | JU32: 207+300 | JV32: 207+400 | JW32: 207+500 | JX32: 207+600 | JY32: 207+700 | JZ32: 207+800 | KA32: 207+900 | KB32: 208+000 | KC32: 208+100 | KD32: 208+200 | KE32: 208+300 | KF32: 208+400 | KG32: 208+500 | KH32: 208+600 | KI32: 208+700 | KJ32: 208+800 | KK32: 208+900 | KL32: 209+000 | KM32: 209+100 | KN32: 209+200 | KO32: 209+300 | KP32: 209+400 | KQ32: 209+500 | KR32: 209+600 | KS32: 209+700 | KT32: 209+800 | KU32: 209+900 | KV32: 210+000 | KW32: 210+100 | KX32: 210+200 | KY32: 210+300 | KZ32: 210+400 | LA32: 210+500 | LB32: 210+600 | LC32: 210+700 | LD32: 210+800 | LE32: 210+900 | LF32: 211+000 | LG32: 211+100 | LH32: 211+200 | LI32: 211+300 | LJ32: 211+400 | LK32: 211+500 | LL32: 211+600 | LM32: 211+700 | LN32: 211+800 | LO32: 211+900 | LP32: 212+000 | LQ32: 212+100 | LR32: 212+200 | LS32: 212+300 | LT32: 212+400 | LU32: 212+500 | LV32: 212+600 | LW32: 212+700 | LX32: 212+800 | LY32: 212+900 | LZ32: 213+000 | MA32: 213+100 | MB32: 213+200 | MC32: 213+300 | MD32: 213+400 | ME32: 213+500 | MF32: 213+600 | MG32: 213+700 | MH32: 213+800 | MI32: 213+900 | MJ32: 214+000 | MK32: 214+100 | ML32: 214+200 | MM32: 214+300 | MN32: 214+400 | MO32: 214+500 | MP32: 214+600 | MQ32: 214+700 | MR32: 214+800 | MS32: 214+900 | MT32: 215+000 | MU32: 215+100 | MV32: 215+200 | MW32: 215+300 | MX32: 215+400 | MY32: 215+500 | MZ32: 215+600 | NA32: 215+700 | NB32: 215+800 | NC32: 215+900 | ND32: 216+000 | NE32: 216+100 | NF32: 216+200 | NG32: 216+300 | NH32: 216+400 | NI32: 216+500 | NJ32: 216+600 | NK32: 216+700 | NL32: 216+800 | NM32: 216+900 | NN32: 217+000 | NO32: 217+100 | NP32: 217+200 | NQ32: 217+300 | NR32: 217+400 | NS32: 217+500 | NT32: 217+600 | NU32: 217+700 | NV32: 217+800 | NW32: 217+900 | NX32: 218+000 | NY32: 218+100 | NZ32: 218+200 | OA32: 218+300 | OB32: 218+400 | OC32: 218+500 | OD32: 218+600 | OE32: 218+700 | OF32: 218+800 | OG32: 218+900 | OH32: 219+000 | OI32: 219+100 | OJ32: 219+200 | OK32: 219+300 | OL32: 219+400 | OM32: 219+500 | ON32: 219+600 | OO32: 219+700 | OP32: 219+800 | OQ32: 219+900 | OR32: 220+000 | OS32: 220+100 | OT32: 220+200 | OU32: 220+300 | OV32: 220+400 | OW32: 220+500 | OX32: 220+600 | OY32: 220+700 | OZ32: 220+800 | PA32: 220+900 | PB32: 221+000 | PC32: 221+100 | PD32: 221+200 | PE32: 221+300 | PF32: 221+400 | PG32: 221+500 | PH32: 221+600 | PI32: 221+700 | PJ32: 221+800 | PK32: 221+900 | PL32: 222+000 | PM32: 222+100 | PN32: 222+200 | PO32: 222+300 | PP32: 222+400 | PQ32: 222+500 | PR32: 222+600 | PS32: 222+700 | PT32: 222+800 | PU32: 222+900 | PV32: 223+000 | PW32: 223+100 | PX32: 223+200 | PY32: 223+300 | PZ32: 223+400 | QA32: 223+500 | QB32: 223+600 | QC32: 223+700 | QD32: 223+800 | QE32: 223+900 | QF32: 224+000 | QG32: 224+100 | QH32: 224+200 | QI32: 224+300 | QJ32: 224+400 | QK32: 224+500 | QL32: 224+600 | QM32: 224+700 | QN32: 224+800 | QO32: 224+900 | QP32: 225+000 | QQ32: 225+100 | QR32: 225+200 | QS32: 225+300 | QT32: 225+400 | QU32: 225+500 | QV32: 225+600 | QW32: 225+700 | QX32: 225+800 | QY32: 225+900 | QZ32: 226+000 | RA32: 226+100 | RB32: 226+200 | RC32: 226+300
C33: بنود أساسية
B34: 1 | C34: طبقة إعادة التدوير (FDR) | GH34: 198+285 | GI34: 198+300 | GU34: 199+535 | HJ34: 201+050 | HK34: منطقة البوابة | HL34: 201+290 | HR34: 201+810 | IC34: 202+920 | II34: 203+550 | IL34: 203+850 | IO34: 204+150 | IZ34: 205+200 | JB34: 205+400 | JF34: 205+800 | RB34: 226+280 | RE34: طبقة إعادة التدوير (FDR)
B35: 2 | C35: رش طبقة التشريب (MCO) | HC35: 200+360 | HJ35: 201+050 | HK35: منطقة البوابة | HL35: 201+290 | HM35: 201+300 | ID35: 203+000 | IH35: 203+400 | IJ35: 203+600 | JF35: 205+800 | JM35: 207+500 | KA35: 207+900 | KE35: 208+300 | KM35: 209+100 | LB35: 210+700 | LE35: 210+900 | RB35: 226+280 | RE35: رش طبقة التشريب (MCO)
B36: 3 | C36: طبقة الاسفلت المحسن | JF36: 205+800 | JI36: 206+160 | JJ36: خارج | JK36: المواصفات | JL36: 206+400 | JO36: 206+700. | LE36: 210+940 | LK36: 211+580 | LR36: 212+270 | MA36: 213+150 | ME36: 213+550 | MT36: 215+025 | NO36: 217+140 | NV36: 217+830 | RB36: 226+280 | RE36: طبقة الاسفلت المحسن
C37: بنود إضافية
B38: 1 | C38: طبقة أساس حبيبي | HB38: 200+250 | HJ38: 201+050 | HK38: منطقة البوابة | HL38: 201+290 | HM38: 201+300 | HU38: 202+210 | JF38: 205+800 | JK38: 206+300 | JO38: 206+700 | KA38: 207+900 | RB38: 226+280 | RE38: طبقة أساس حبيبي
B39: 2 | C39: الطريق الخدمي | DN39: 191+000 | IC39: 202+900 | RC39: 226+300 | RE39: الطريق الخدمي
C42: ****** | E42: الرواد اخر محطة 208+300
D44: الإجمالي | AF44: الإجمالي | CC44: قطاع B
D45: حسن علام | AF45: نيوم | BD45: اوراسكوم | CJ45: الرواد
D46: الوصف | G46: بداية المحطة | K46: نهاية المحطة | P46: الطول (م.ط) | U46: الإجمالي | AC46: الوصف | AI46: بداية المحطة | AM46: نهاية المحطة | AR46: الطول (م.ط) | AW46: الإجمالي | BD46: الوصف | BJ46: بداية المحطة | BN46: نهاية المحطة | BS46: الطول (م.ط) | BX46: الإجمالي | CJ46: الوصف | CP46: بداية المحطة | CT46: نهاية المحطة | CY46: الطول (م.ط) | DD46: الإجمالي
D47: طبقة إعادة التدوير | G47: -0.64 | K47: 44.426 | P47: =(K47-G47)*1000 -> 45066 | AC47: طبقة إعادة التدوير | AI47: 45.58 | AM47: 89.867 | AR47: =(AM47-AI47)*1000 -> 44287 | BD47: طبقة إعادة التدوير | BJ47: 90.58 | BN47: 159.96 | BS47: =(BN47-BJ47)*1000 -> 69380 | CJ47: طبقة إعادة التدوير | CP47: 189.84 | CT47: 226.28 | CY47: =(CT47-CP47)*1000 -> 36440
G48: 45 | K48: 45.59 | P48: =(K48-G48)*1000 -> 590 | U48: =P47+P48 -> 45656 | AI48: 90 | AM48: 90.58 | AR48: =(AM48-AI48)*1000 -> 580 | BJ48: 160.08 | BN48: 162.22 | BS48: =(BN48-BJ48)*1000 -> 2140 | CD48: =(165-BN48)*1000 -> 2780 | CP48: 0 | CT48: 0 | CY48: =(CT48-CP48)*1000 -> 0 | DD48: =CY47+CY48 -> 36440
D49: طبقة الأساس | G49: -0.64 | K49: 44.426 | P49: =(K49-G49)*1000 -> 45066 | AI49: 0 | AM49: 0 | AR49: =(AM49-AI49)*1000 -> 0 | AW49: =AR47+AR48+AR49 -> 44867 | BJ49: 0 | BN49: 0 | BS49: =(BN49-BJ49)*1000 -> 0 | BX49: =SUM(BS47:BW51) -> 71520 | CD49: المتبقي من الأساس | CJ49: طبقة الأساس | CP49: 189.84 | CT49: 226.28 | CY49: =(CT49-CP49)*1000 -> 36440
G50: 45 | K50: 45.59 | P50: =(K50-G50)*1000 -> 590 | AC50: طبقة الأساس | AI50: 45.58 | AM50: 89.867 | AR50: =(AM50-AI50)*1000 -> 44287 | BJ50: 0 | BN50: 0 | BS50: =(BN50-BJ50)*1000 -> 0 | CP50: 0 | CT50: 0 | CY50: =(CT50-CP50)*1000 -> 0
...

Sheet الاعمال المنجزة 23 06 2026
B1: مشروع صيانة طريق اوباري غات
B2: الاعمال المنجزة للمرحلة الاولي | AF2: التاريخ | AH2: 46196 | AL2: =AH2 -> 46196
B3: القطاع (A)
B4: البند | C4: الوصف | H4: اعمال اليوم (م.ط) | L4: الإجمالي (م.ط) | P4: المستهدف اليومي | T4: الزيادة / النقصان | W4: ملاحظات | AX4: الاعمال السابقة (م.ط)
C5: بنود أساسية | AL5: إعادة التدوير | AM5: الأساس الحبيبي | AN5: طبقة التشريب | AO5: الاسفلت المحسن | AP5: الطريق الخدمي | AQ5: المستهدف
B6: 1 | C6: طبقة إعادة التدوير (FDR) | H6: 600 | L6: =AX6+H6 -> 112243 | P6: 500 | T6: =H6-P6 -> 100 | AL6: =L6 -> 112243 | AM6: =L11 -> 109373 | AN6: =L7 -> 109373 | AO6: =L8 -> 107363 | AP6: =L12 -> 115363 | AQ6: 115363 | AX6: 111643
B7: 2 | C7: رش طبقة التشريب (MCO) | H7: 0 | L7: =AX7+H7 -> 109373 | P7: 500 | T7: =H7-P7 -> -500 | AX7: 109373
B8: 3 | C8: طبقة الاسفلت المحسن | H8: 590 | L8: =AX8+H8 -> 107363 | P8: 500 | T8: =H8-P8 -> 90 | AX8: 106773
C9: بنود إضافية
B10: 1 | C10: فرمة اولي بدون اسمنت(FDR) | H10: 0 | L10: =AX10+H10 -> 115363 | P10: 500 | T10: =H10-P10 -> -500 | AX10: 115363
B11: 2 | C11: طبقة أساس حبيبي | H11: 0 | L11: =AX11+H11 -> 109373 | P11: 500 | T11: =H11-P11 -> -500 | AX11: 109373
B12: 3 | C12: الطريق الخدمي | H12: 0 | L12: =AX12+H12 -> 115363 | AX12: 115363
B14: القطاع (B)
B15: البند | C15: الوصف | H15: اعمال اليوم (م.ط) | L15: الإجمالي (م.ط) | P15: المستهدف اليومي | T15: الزيادة / النقصان | W15: ملاحظات | AX15: الاعمال السابقة (م.ط)
C16: بنود أساسية | AL16: إعادة التدوير | AM16: الأساس الحبيبي | AN16: طبقة التشريب | AO16: الاسفلت المحسن | AP16: الطريق الخدمي | AQ16: المستهدف
B17: 1 | C17: طبقة إعادة التدوير (FDR) | H17: 460 | L17: =AX17+H17 -> 107960 | P17: 500 | T17: =H17-P17 -> -40 | AL17: =L17 -> 107960 | AM17: =L22 -> 106110 | AN17: =L18 -> 104930 | AO17: =L19 -> 102560 | AP17: =L23 -> 110900 | AQ17: 110900 | AX17: 107500
B18: 2 | C18: رش طبقة التشريب (MCO) | H18: 0 | L18: =AX18+H18 -> 104930 | P18: 500 | T18: =H18-P18 -> -500 | AX18: 104930
B19: 3 | C19: طبقة الاسفلت المحسن | H19: 0 | L19: =AX19+H19 -> 102560 | P19: 500 | T19: =H19-P19 -> -500 | AX19: 102560
C20: بنود إضافية
B21: 1 | C21: فرمة اولي بدون اسمنت(FDR) | H21: 0 | L21: =AX21+H21 -> 110780 | P21: 500 | T21: =H21-P21 -> -500 | AX21: 110780 | BB21: 140
B22: 2 | C22: طبقة أساس حبيبي | H22: 600 | L22: =AX22+H22 -> 106110 | P22: 500 | T22: =H22-P22 -> 100 | AX22: 105510
B23: 3 | C23: الطريق الخدمي | H23: 0 | L23: =AX23+H23 -> 110900 | AX23: 110900
B25: اجمالي المنجز للمرحلة الاولي
B26: البند | C26: الوصف | H26: اعمال اليوم (م.ط) | L26: الإجمالي (م.ط) | P26: الجاهز للعمل في البنذ | U26: ملاحظات | AX26: الاعمال السابقة (م.ط)
C27: بنود أساسية | AL27: إعادة التدوير | AM27: الأساس الحبيبي | AN27: طبقة التشريب | AO27: الاسفلت المحسن | AP27: الطريق الخدمي | AQ27: المستهدف
B28: 1 | C28: طبقة إعادة التدوير (FDR) | H28: =H6+H17 -> 1060 | L28: =AX28+H28 -> 220203 | P28: =L32-L28 -> 5940 | U28: الجاهز للعمل بالبنذ (منفذ فرمة اولي وغير منفذ فرمة تانية) | AL28: =L28 -> 220203 | AM28: =L33 -> 215483 | AN28: =L29 -> 214303 | AO28: =L30 -> 209923 | AP28: =L34 -> 226263 | AQ28: 226263 | AX28: =AX6+AX17 -> 219143
B29: 2 | C29: رش طبقة التشريب (MCO) | H29: =H7+H18 -> 0 | L29: =AX29+H29 -> 214303 | P29: =L33-L29 -> 1180 | U29: الجاهز للعمل بالبنذ (منفذ اساس وغير مرشوش mc) | AX29: =AX7+AX18 -> 214303
B30: 3 | C30: طبقة الاسفلت المحسن | H30: =H8+H19 -> 590 | L30: =AX30+H30 -> 209923 | P30: =L29-L30 -> 4380 | U30: الجاهز للعمل بالبنذ (مرشوش mc وغير منفذ اسفلت) | AX30: =AX8+AX19 -> 209333
C31: بنود إضافية
B32: 1 | C32: فرمة اولي بدون اسمنت(FDR) | H32: =H10+H21 -> 0 | L32: =AX32+H32 -> 226143 | P32: =226263-L32 -> 120 | U32: الجاهز للعمل بالبنذ (المتبقي من القطاع وغير مفروم فرمة اولي) | AX32: =AX10+AX21 -> 226143
B33: 2 | C33: طبقة أساس حبيبي | H33: =H11+H22 -> 600 | L33: =AX33+H33 -> 215483 | P33: =L28-L33 -> 4720 | U33: الجاهز للعمل بالبنذ (منفذ فرمة ثانية وغير منفذ اساس) | AX33: =AX11+AX22 -> 214883
B34: 3 | C34: الطريق الخدمي | H34: =H12+H23 -> 0 | L34: =AX34+H34 -> 226263 | P34: =226263-L34 -> 0 | U34: الجاهز للعمل بالبنذ (الغير مفتوح طريق خدمي) | AX34: =AX12+AX23 -> 226263
B36: طول الطريق الخدمي العامل | H36: =L34-L30 -> 16340 | L36: كيلومتر
